---
title: Kotlin的异常处理
sidebar_position: 5
keywords:
  - Android
  - Kotlin
tags:
  - Android
  - Kotlin
  - 学习笔记
  - Java
last_update:
  date: 2023-08-08
  author: EasonShu
---
# 一 Kotlin的异常处理
Kotlin是一种现代的、静态类型的编程语言，它在异常处理方面提供了简洁而强大的机制。Kotlin的异常处理机制建立在Java异常处理机制的基础上，但进行了一些改进，使代码更加清晰和安全。

在Kotlin中，异常被分为两种类型：可检查异常（checked exceptions）和不可检查异常（unchecked exceptions）。

1. **不可检查异常（Unchecked Exceptions）**：
   Kotlin中的不可检查异常指的是继承自`RuntimeException`的异常类，它们不需要在函数签名中声明或捕获。这意味着你不需要显式地处理这些异常，但仍然可以选择捕获它们，以便在必要时执行特定的异常处理逻辑。

   示例：
   ```kotlin
   fun main() {
       val list = listOf(1, 2, 3)
       try {
           println(list[10]) // This will throw an IndexOutOfBoundsException
       } catch (e: IndexOutOfBoundsException) {
           println("Caught exception: $e")
       }
   }
   ```

2. **可检查异常（Checked Exceptions）**：
   Kotlin中的可检查异常与Java不同，Kotlin没有引入这种类型的异常。这意味着在Kotlin中，函数不需要声明它们可能会抛出的异常。这样可以减少代码中的冗余，并提高代码的清晰性。

   示例：
   ```kotlin
   // In Kotlin, you don't need to declare checked exceptions
   // This is unlike Java where you would need to declare them in the method signature or handle them using try-catch
   fun readFile(fileName: String): String {
       // Implementation to read a file
   }
   ```

3. **异常处理**：
   在Kotlin中，异常处理使用`try`、`catch`和`finally`块来完成。`try`块中包含可能会抛出异常的代码，而`catch`块用于捕获并处理异常。`finally`块中的代码无论是否发生异常都会被执行。

   示例：
   ```kotlin
   fun main() {
       val numerator = 10
       val denominator = 0

       try {
           val result = numerator / denominator
           println("Result: $result")
       } catch (e: ArithmeticException) {
           println("Caught exception: $e")
       } finally {
           println("Finally block executed")
       }
   }
   ```
    输出：
    ```
    Caught exception: java.lang.ArithmeticException: / by zero
    Finally block executed
    ```

4. **自定义异常**：
    在Kotlin中，可以通过继承`Exception`类来创建自定义异常。通常，自定义异常类应该包含一个构造函数，该构造函数接受一个字符串参数，该参数表示异常的详细信息。

    示例：
    ```kotlin
    class CustomException(message: String) : Exception(message)

    fun main() {
        try {
            throw CustomException("This is a custom exception")
        } catch (e: CustomException) {
            println("Caught exception: $e")
        }
    }
    ```
      输出：
      ```
      Caught exception: CustomException: This is a custom exception
      ```


